<mujoco model="model">
  <include file="Empty_scene.xml"/> <!-- so we can use the ready scene !-->


  <!-- define assets!-->
  <asset>
    <material name="white" rgba="1 1 1 1"/> <!--color white, to use it we add material="white" to the element!-->
    <material name="red" rgba=".9 0 0 1"/>
    <material name="green"  rgba="0 0.9 0 1"/>
    <material name="yellow" rgba="0.8 1 0 1"/>

    <texture name="texcarpet" type="2d" file="floor.png"/>
    <material name="carpet" texture="texcarpet"/>

  </asset>

  <option solver="CG" tolerance="1e-6"/>

  <size nconmax="3000" njmax="3000" nstack="5000"/>



  <worldbody>
    <!--<camera pos="0 0 0" mode="track"/> <!-keep an entire mechanism in view.!-->
    <!-- the floor we work on !-->
    <geom type="plane" size="12 12 0.1" pos="0 0 0.1" material="carpet"/>

    <body pos="0 5 0">
      <geom type="sphere" size="0.01 0 0"/>
    </body>
    <!--the walls !-->

    <body name="wall" pos="0 6 1">
      <geom type="box" size="6 0.2 1" material="red"/> <!--size = " length width higth"!-->
    </body>

    <body name="wall2-1" pos="6 -4 1">
      <geom type="box" size="0.2 2 1" material="red"/> <!--size = " length width higth"!-->
    </body>
    <body name="wall2-2" pos="6 4 1">
      <geom type="box" size="0.2 2 1" material="red"/> <!--size = " length width higth"!-->
    </body>

    <body name="wall3" pos="0 -6 1">
      <geom type="box" size="6 0.2 1" material="red"/> <!--size = " length width higth"!-->
    </body>

    <body name="wall4" pos="-6 0 1">
      <geom type="box" size="0.2 6 1" material="red"/> <!--size = " length width higth"!-->
    </body>

    <body name="out-wall" pos="8 -6 1">
      <geom type="box" size="2 0.2 1" material="red"/> <!--size = " length width higth"!-->
    </body>
    <body name="out-wall2-2" pos="10 2 1">
      <geom type="box" size="0.2 8 1" material="red"/> <!--size = " length width higth"!-->
    </body>

    <!--the agents!-->


    <body name="agent1" pos="2 0 0">

      <geom type="sphere" size="0.5" pos="0 0 0.6" material="green"/>

      <geom name="pointarrow" pos="0.5 0 0.8" size="0.1 0.1 0.1" type="box" material="green"/>

      <joint axis="1 0 0" name="ballx" pos="0 0 0" type="slide"/>
      <joint axis="0 1 0" name="bally" pos="0 0 0" type="slide"/>
      <joint axis="0 0 1" limited="false" name="rot" pos="0 0 0" type="hinge"/>
    </body>

    <body name="agent2" pos="-3 4 0">

      <geom type="sphere" size="0.5" pos="0 0 0.6" material="yellow"/>

      <geom name="pointarrow2" pos="0.5 0 0.8" size="0.1 0.1 0.1" type="box" material="yellow"/>

      <joint axis="1 0 0" name="ballx2" pos="0 0 0" type="slide"/>
      <joint axis="0 1 0" name="bally2" pos="0 0 0" type="slide"/>
      <joint axis="0 0 1" limited="false" name="rot2" pos="0 0 0" type="hinge"/>
    </body>

    <body name="agent3" pos="3 2 0">

      <geom type="sphere" size="0.5" pos="0 0 0.6" material="white"/>

      <geom name="pointarrow3" pos="0.5 0 0.8" size="0.1 0.1 0.1" type="box" material="white"/>

      <joint axis="1 0 0" name="ballx3" pos="0 0 0" type="slide"/>
      <joint axis="0 1 0" name="bally3" pos="0 0 0" type="slide"/>
      <joint axis="0 0 1" limited="false" name="rot3" pos="0 0 0" type="hinge"/>
    </body>

			<body name="door" pos="6 0 1" >
				<inertial diaginertia="0.0914 0.0522 0.0437" mass="2.4346" pos="0.0297 -0.0015 0" quat="0.7011 0 0 0.7131"></inertial>
        <!--the range in the joint : door_hinge lets us determine how much the door can rotate (how open it can be)!-->
				<joint armature="0.01" axis="0 0 1" damping="1" frictionloss="0.1" limited="true" name="door_hinge" pos="0.25 0 0" range="0 50" type="hinge"></joint>
				<geom condim="3" friction="1 1 1" size="0.2 2 1.1" type="box"></geom>
				<geom pos="0.2 0 0" size="0.05 0.05 0.25" type="box"></geom>
        <geom pos="-0.15 -0.065 -0.051" size="0.05 0.015 0.01" type="box"></geom>
				<geom pos="-0.15 -0.065 0.051" size="0.05 0.015 0.01" type="box"></geom>
				<geom pos="-0.15 -0.09 0" size="0.05 0.011 0.06" type="box"></geom>
				<geom pos="-0.15 -0.16 0" size="0.01 0.01 0.05" type="box" euler="0 -1.5708 0"></geom>


        <body name="latch" pos="-0.16 -0.065 0">
					<inertial diaginertia="0.0038 0.0036 0.0002" mass="0.4657" pos="0.0042 -0.001 0" quat="0.504 0.504 0.496 0.496"></inertial>
					<geom name="latch1" condim="1" size="0.15 0.01 0.0375" type="box"></geom>
					<geom name="latch2" pos="0.125 -0.03 0" size="0.01 0.01 0.02" type="box"></geom>
					<!--used when there is a door lock
          <joint axis="1 0 0" frictionloss="0.1" limited="true" name="latch_joint" pos="0 0 0" range="0 0.15" type="slide"/>
          !-->
				</body>
			</body>


      <body name="Key" pos="-4 0 1">
          <geom name="teeth" type="box" pos="0 0.5 0" size="0.02 0.3 0.08" condim="3" friction="1 0.001 0.001"></geom>
          <geom name="Pad" type="cylinder" pos="0 -0.035 0" size="0.4 0.02" euler="0 1.57 0" condim="3" friction="1 0.001 0.001"></geom>
          <joint name="key" type="hinge" axis="0 1 0" pos="0 0 0" limited="true" range="0 1.57" stiffness="0.02" damping="0.001"></joint>
          <joint axis="1 0 0" name="keyx" pos="0 0 0" type="slide"/>
          <joint axis="0 1 0" name="key_y" pos="0 0 0" type="slide"/>
          <joint axis="0 0 1" limited="false" name="key_rotate" pos="0 0 0" type="hinge"/>

      </body>
  </worldbody>

  <!--we need to add a sensor to the door to open it and actuator to the balls!-->

  <actuator>
    <!--door actuator!-->
    <position kp="10" ctrlrange="0 50" name="door_act" joint="door_hinge" ctrllimited="true"/>

    <!--ball actuator!-->
    <position kp="10" ctrlrange="-3 50" name="aballx1" joint="ballx" ctrllimited="true"/>
    <position kp="10" ctrlrange="0 50" name="abally1" joint="bally" ctrllimited="true"/>
    <position kp="10" ctrlrange="-1 1" name="aballrot1" joint="rot" ctrllimited="true"/>


    <!--ball actuator!-->
    <position kp="10" ctrlrange="0 50" name="aballx2" joint="ballx2" ctrllimited="true"/>
    <position kp="10" ctrlrange="0 50" name="abally2" joint="bally2" ctrllimited="true"/>
    <position kp="10" ctrlrange="0 50" name="aballrot2" joint="rot2" ctrllimited="true"/>


    <!--ball actuator!-->
    <position kp="10" ctrlrange="0 50" name="aballx3" joint="ballx3" ctrllimited="true"/>
    <position kp="10" ctrlrange="0 50" name="abally3" joint="bally3" ctrllimited="true"/>
    <position kp="10" ctrlrange="0 50" name="aballrot3" joint="rot3" ctrllimited="true"/>
</actuator>

  <sensor>
    <jointpos name="sdoor_hinge" joint="door_hinge"/>
  </sensor>

</mujoco>
